Workbook

Sheet Membership-Driven (36m)
A1: Membership-Driven Court Revenue Model – 36 months (Monthly) – v4 (Seasonality)
A2: Seasonality Index scales demand for member & non-member reservations and open play.
A4: INPUTS – Facility & Schedule | E4: INPUTS – Utilization Baselines (Members) | H4: SEASONALITY – Monthly Index
A5: Courts (count) | B5: 8 | E5: Baseline utilization – Peak (weekday) – Members | F5: 0.75 | H5: M1 | I5: 2
A6: Days open per week | B6: 7 | E6: Baseline utilization – Off-peak (weekday) – Members | F6: 0.4 | H6: M2 | I6: 1.5
A7: Hours open per day | B7: 16 | E7: Baseline utilization – Peak (weekend) – Members | F7: 0.85 | H7: M3 | I7: 1.5
A8: Peak hours share of day | B8: 0.6 | E8: Baseline utilization – Off-peak (weekend) – Members | F8: 0.5 | H8: M4 | I8: 1.2
A9: Weekend share of days | B9: 0.28571429 | H9: M5 | I9: 1
A10: Reservation share of total court time (vs open play) | B10: 0.25 | H10: M6 | I10: 1
A11: INPUTS – Pricing | E11: INPUTS – Policy & Behavior (Members) | H11: M7 | I11: 1
A12: Peak rate – Non-member ($/court-hr) | B12: 40 | E12: No-show rate (paid/no-refund portion) | F12: 0.05 | H12: M8 | I12: 1
A13: Off-peak rate – Non-member ($/court-hr) | B13: 30 | E13: Member booking share of reservations (target) | F13: 0.7 | H13: M9 | I13: 1.2
A14: Member discount on court rate | B14: 0.25 | E14: Booking window uplift (members vs non) | F14: 0.05 | H14: M10 | I14: 1.5
A15: Open Play price – Member ($/session) | B15: 5 | H15: M11 | I15: 1.5
A16: Open Play price – Non-member ($/session) | B16: 8 | H16: M12 | I16: 2
A17: Open Play session length (min) | B17: 60 | H17: Notes:
A19: INPUTS – Membership Growth (drives demand) | E19: INPUTS – Non-member Reservation Demand
A20: Starting Members (Month 1) | B20: 100 | E20: Baseline utilization – Peak (weekday) – Non-members | F20: 0.5
A21: Monthly Member Growth Rate (%) | B21: 0.05 | E21: Baseline utilization – Off-peak (weekday) – Non-members | F21: 0.4
A22: Max Member Capacity (optional) | B22: 1000 | E22: Baseline utilization – Peak (weekend) – Non-members | F22: 0.5
A23: % Members who reserve monthly | B23: 0.5 | E23: Baseline utilization – Off-peak (weekend) – Non-members | F23: 0.4
A24: Avg reservations per reserving member / month | B24: 2 | E24: Marketing uplift – Non-members (reservations) | F24: 0.1
A25: Avg reservation duration (min) | B25: 60 | E25: Non-member reservation cap (% of reservation capacity) | F25: 1
A26: Avg open-play sessions / member / month | B26: 12
A27: Open Play players per court capacity (per hour) | B27: 6
A29: HELPERS | E29: Blended Utilization
A30: Total Court Hours / month | B30: =B7*B5*4.33*B6 -> 3879.68 | E30: Blended Peak Utilization – Members | F30: =(1-B8)*F5 + B8*F7 -> 0.81
A31: Peak Hours / month | B31: =B30*B8 -> 2327.808 | E31: Blended Off-Peak Utilization – Members | F31: =(1-B8)*F6 + B8*F8 -> 0.46
A32: Off-Peak Hours / month | B32: =B30*(1-B8) -> 1551.872
A33: Open Play Hours Share | B33: =(1-B10) -> 0.75 | E33: Blended Utilization – Non-members
E34: Blended Peak Utilization – Non-members | F34: =(1-B8)*F20 + B8*F22 -> 0.5
E35: Blended Off-Peak Utilization – Non-members | F35: =(1-B8)*F21 + B8*F23 -> 0.4
E37: Reservation Capacity (attended hours cap)
E38: Reservation Capacity Hours / month | F38: =(B31*F30 + B32*F31)*B10 -> 649.8464
A39: Reservation Duration (hours) | B39: =B25/60 -> 1
A40: Open Play Session Length (hours) | B40: =B17/60 -> 1 | E40: Reservation Rates (blended)
E41: Blended Non-member Reservation Rate ($/hr) | F41: =(B12*B31 + B13*B32)/(B31+B32) -> 36
E42: Blended Member Reservation Rate ($/hr) | F42: =F41*(1-B14) -> 27
A44: Month | B44: Seasonality Index | C44: Members | D44: Member Reservation Hours (raw) | E44: Member Reservation Hours (capped) | F44: Non-member Reservation Demand Hours | G44: Non-member Reservation Hours (actual) | H44: Avg Reservation Rate ($/hr) | I44: Reservation Revenue (attended) | J44: No-show Revenue | K44: Member Open Play Hours (raw) | L44: Member Open Play Hours (capped) | M44: Member Open Play Sessions | N44: Member Open Play Revenue | O44: Non-member Open Play Hours | P44: Non-member Open Play Sessions | Q44: Non-member Open Play Revenue | R44: TOTAL Court Revenue ($/mo)
A45: M1 | B45: =INDEX($I$5:$I$16, 1+MOD(1-1,12)) -> 2 | C45: =MIN(B20,$B$22) -> 100 | D45: =C45*$B$23*$B$24*$B$39*B45 -> 200 | E45: =MIN(D45, $F$38) -> 200 | F45: =(($B$31*$F$34*$B$10) + ($B$32*$F$35*$B$10))*(1+$F$24)*B45 -> 981.55904 | G45: =MIN(F45, MAX($F$38-E45,0), $F$25*$F$38) -> 449.8464 | H45: =IFERROR(($F$42*E45 + $F$41*G45)/(E45+G45),0) -> 33.230115 | I45: =(E45+G45)*H45 -> 21594.47 | J45: =H45*(E45+G45)*$F$12 -> 1079.7235 | K45: =C45*$B$26*$B$40*B45 -> 2400 | L45: =MIN(K45, $B$30*(1-$B$10)) -> 2400 | M45: =IFERROR(L45/$B$40,0) -> 2400 | N45: =M45*$B$15 -> 12000 | O45: =MAX($B$30*(1-$B$10)-L45,0) -> 509.76 | P45: =IFERROR(O45/$B$40,0) -> 509.76 | Q45: =P45*$B$16 -> 4078.08 | R45: =I45+J45+N45+Q45 -> 38752.274
...
