Workbook
Name CafeCOGS: Assumptions!B27
Name CafeGross: Assumptions!B26
Name CafeHrs: Assumptions!B32
Name CafeWage: Assumptions!B33
Name Cleaning: Assumptions!B39
Name CoachHrs: Assumptions!B30
Name CoachWage: Assumptions!B31
Name DaysOpenPerWeek: Assumptions!B9
Name FrontDeskHrs: Assumptions!B28
Name FrontDeskWage: Assumptions!B29
Name HoursOpenPerDay: Assumptions!B10
Name Insurance: Assumptions!B36
Name LeagueTeamFee: Assumptions!B22
Name LeagueTeams: Assumptions!B21
Name LessonRate: Assumptions!B20
Name LessonsPerWeek: Assumptions!B19
Name LoanAPR: Assumptions!B43
Name LoanPrincipal: Assumptions!B42
Name LoanTerm: Assumptions!B44
Name Marketing: Assumptions!B37
Name Members: Assumptions!B17
Name MembershipFee: Assumptions!B18
Name MiscOpex: Assumptions!B40
Name MonthlyCOGS: OPEX!$E$6
Name MonthlyDebtService: Financing!$I$3
Name MonthlyOpex: OPEX!$B$11
Name MonthlyPayroll: 'Staffing & Payroll'!$E$7
Name NumCourts: Assumptions!B8
Name OpeningCash: Assumptions!B41
Name PeakHoursShare: Assumptions!B11
Name RateOffPeak: Assumptions!B15
Name RatePeak: Assumptions!B14
Name Rent: Assumptions!B34
Name RetailCOGS: Assumptions!B25
Name RetailGross: Assumptions!B24
Name SeasonsPerYear: Assumptions!B23
Name Software: Assumptions!B38
Name TotalCapEx: 'CapEx & Sources'!E19
Name TotalRevenueRange: 'Revenue Model'!$I$5:$I$39
Name TurnTimeMin: Assumptions!B16
Name Utilities: Assumptions!B35
Name UtilOffPeak: Assumptions!B13
Name UtilPeak: Assumptions!B12

Sheet Assumptions
A1: Smashpoint Pickleball – Master Assumptions
A3: Category | B3: Value | C3: Notes
A4: Project Name | B4: Smashpoint Pickleball
A5: Location (City/State) | B5: Lorton, VA
A6: Start Date (MMM-YYYY) | B6: Jan-2026
A7: Number of Courts | B7: 8
A8: Days Open / Week | B8: 7
A9: Hours Open / Day | B9: 14
A10: Peak Hours Share (of day) | B10: 0.45
A11: Utilization – Peak | B11: 0.7
A12: Utilization – Off-Peak | B12: 0.4
A13: Court Rate – Peak ($/hr) | B13: 40
A14: Court Rate – Off-Peak ($/hr) | B14: 30
A15: Turn Time Between Bookings (min) | B15: 5
A16: Initial Members | B16: 50
A17: Membership Fee ($/mo) (ARPU) | B17: ='Memberships Revenue'!D52 -> 92.05
A18: Membership Growth Rate | B18: 0.05
A19: Lessons per Week | B19: 24 | C19: Ideally 24 per week
A20: Lesson Rate ($) | B20: 65
A21: League Teams per Season | B21: 12 | C21: Ideally 28 teams
A22: League Team Fee ($ per season) | B22: 250
A23: Seasons per Year | B23: 4
A24: Retail Gross ($/mo) | B24: 3000 | C24: Ideally want this to be around 4500 per month
A25: Retail COGS % | B25: 0.55
A26: Cafe Gross ($/mo) | B26: 5000 | C26: Ideally want this to be around 5000 per month
A27: Cafe COGS % | B27: 0.45
A28: Front Desk Hours / Week | B28: 196
A29: Front Desk Wage ($/hr) | B29: 18
A30: Coaches Hours / Week | B30: 40 | C30: Should be around 40 per week
A31: Coach Wage ($/hr) | B31: 30
A32: Cafe Hours / Week | B32: 60
A33: Cafe Wage ($/hr) | B33: 17
A34: Base Rent ($/mo) | B34: 40000 | C34: Originally 30K but taking conservative approach
A35: Utilities ($/mo) | B35: 6000 | C35: Originally 4.5K but taking conservative approach
A36: Insurance ($/mo) | B36: 4000 | C36: Estimated to be 2K but doubling value for conservative approach
A37: Marketing ($/mo) | B37: 4000 | C37: Estimated to be 4K but emphasizing substantial marketing campaign
A38: Software ($/mo) | B38: 2000 | C38: Estimated to be 0.8K but emphasizing strong software support
A39: Cleaning & Supplies ($/mo) | B39: 3000 | C39: Originally 1.5K but taking conservative approach
A40: Misc. Opex ($/mo) | B40: 2000 | C40: Estimated to be 1.2K but doubling value for conservative approach
A41: Opening Cash Balance ($) | B41: 100000
...

Sheet CapEx & Sources
A1: Capital Expenditures and Sources/Uses
A3: Category | B3: Vendor/Notes | C3: Qty | D3: Unit Cost | E3: Line Total | G3: Sources & Uses
A4: Court surfacing & paint | C4: 8 | D4: 21000 | E4: =C4*D4 -> 168000 | G4: Item | H4: Amount
A5: Portable dividers/fencing | C5: 8 | D5: 4000 | E5: =C5*D5 -> 32000 | G5: Equity (plug) | H5: =H11-H6 -> -1100740
A6: Lighting (LED + install) | C6: 1 | D6: 100000 | E6: =C6*D6 -> 100000 | G6: SBA/Loan Proceeds | H6: =Assumptions!B42 -> 2000000
A7: Electronics (TVs,Tablets, etc.) | C7: 1 | D7: 20000 | E7: =C7*D7 -> 20000
A8: HVAC upgrades | C8: 1 | D8: 70000 | E8: =C8*D8 -> 70000 | G8: Total Sources | H8: =H6+H5 -> 899260
A9: Acoustic treatment | C9: 1 | D9: 70000 | E9: =C9*D9 -> 70000 | G9: Uses: CapEx Total | H9: =E22 -> 799260
A10: Nets & posts | C10: 8 | D10: 1200 | E10: =C10*D10 -> 9600 | G10: Opening Cash Reserve | H10: =Assumptions!B41 -> 100000
A11: Lockers/benches/seating | C11: 1 | D11: 20000 | E11: =C11*D11 -> 20000 | G11: Total Uses | H11: =H9+H10 -> 899260
A12: Pro shop fit-out | C12: 1 | D12: 45000 | E12: =C12*D12 -> 45000
A13: Cafe equipment & fit-out | C13: 1 | D13: 75000 | E13: =C13*D13 -> 75000
A14: Flooring (non-court) | C14: 1 | D14: 40000 | E14: =C14*D14 -> 40000 | G14: Debt Reserve (Surplus Cash) | H14: =ABS(H5) -> 1100740
A15: Permits/design/engineering | C15: 1 | D15: 50000 | E15: =C15*D15 -> 50000
A16: Security System | C16: 1 | D16: 15000 | E16: =C16*D16 -> 15000
A17: Access Control (Doors) | C17: 1 | D17: 12000 | E17: =C17*D17 -> 12000
D20: Subtotal: | E20: =SUM(E4:E19) -> 726600
D21: Contingency (10% of Subtotal): | E21: =E20*0.1 -> 72660
D22: Total CapEx: | E22: =E20+E21 -> 799260

Sheet Financing
A1: Loan Amortization (linked to Assumptions)
H2: Monthly Rate | I2: =Assumptions!B43/12 -> 0.0079166667
A3: Month # | B3: Beg Balance | C3: Payment | D3: Interest | E3: Principal | F3: End Balance | H3: Monthly Payment (PMT) | I3: =PMT(I2, Assumptions!B44, -Assumptions!B42) -> 25879.512
A4: 1 | B4: =Assumptions!B42 -> 2000000 | C4: =$I$3 -> 25879.512 | D4: =B4*$I$2 -> 15833.333 | E4: =C4-D4 -> 10046.178 | F4: =B4-E4 -> 1989953.8
A5: 2 | B5: =F4 -> 1989953.8 | C5: =$I$3 -> 25879.512 | D5: =B5*$I$2 -> 15753.801 | E5: =C5-D5 -> 10125.71 | F5: =B5-E5 -> 1979828.1
A6: 3 | B6: =F5 -> 1979828.1 | C6: =$I$3 -> 25879.512 | D6: =B6*$I$2 -> 15673.639 | E6: =C6-D6 -> 10205.872 | F6: =B6-E6 -> 1969622.2
A7: 4 | B7: =F6 -> 1969622.2 | C7: =$I$3 -> 25879.512 | D7: =B7*$I$2 -> 15592.843 | E7: =C7-D7 -> 10286.669 | F7: =B7-E7 -> 1959335.6
A8: 5 | B8: =F7 -> 1959335.6 | C8: =$I$3 -> 25879.512 | D8: =B8*$I$2 -> 15511.407 | E8: =C8-D8 -> 10368.105 | F8: =B8-E8 -> 1948967.5
A9: 6 | B9: =F8 -> 1948967.5 | C9: =$I$3 -> 25879.512 | D9: =B9*$I$2 -> 15429.326 | E9: =C9-D9 -> 10450.186 | F9: =B9-E9 -> 1938517.3
A10: 7 | B10: =F9 -> 1938517.3 | C10: =$I$3 -> 25879.512 | D10: =B10*$I$2 -> 15346.595 | E10: =C10-D10 -> 10532.916 | F10: =B10-E10 -> 1927984.4
A11: 8 | B11: =F10 -> 1927984.4 | C11: =$I$3 -> 25879.512 | D11: =B11*$I$2 -> 15263.21 | E11: =C11-D11 -> 10616.302 | F11: =B11-E11 -> 1917368.1
A12: 9 | B12: =F11 -> 1917368.1 | C12: =$I$3 -> 25879.512 | D12: =B12*$I$2 -> 15179.164 | E12: =C12-D12 -> 10700.348 | F12: =B12-E12 -> 1906667.7
A13: 10 | B13: =F12 -> 1906667.7 | C13: =$I$3 -> 25879.512 | D13: =B13*$I$2 -> 15094.453 | E13: =C13-D13 -> 10785.059 | F13: =B13-E13 -> 1895882.7
A14: 11 | B14: =F13 -> 1895882.7 | C14: =$I$3 -> 25879.512 | D14: =B14*$I$2 -> 15009.071 | E14: =C14-D14 -> 10870.44 | F14: =B14-E14 -> 1885012.2
A15: 12 | B15: =F14 -> 1885012.2 | C15: =$I$3 -> 25879.512 | D15: =B15*$I$2 -> 14923.013 | E15: =C15-D15 -> 10956.498 | F15: =B15-E15 -> 1874055.7
A16: 13 | B16: =F15 -> 1874055.7 | C16: =$I$3 -> 25879.512 | D16: =B16*$I$2 -> 14836.274 | E16: =C16-D16 -> 11043.237 | F16: =B16-E16 -> 1863012.5
... A123: 120 | B123: =F122 -> 25676.241 | C123: =$I$3 -> 25879.512 | D123: =B123*$I$2 -> 203.27024 | E123: =C123-D123 -> 25676.241 | F123: =B123-E123 -> -3.1286618e-10

Sheet Memberships Revenue
A1: Smashpoint Memberships – Tiers, Pricing, Revenue & KPIs
A4: Tier | B4: Monthly Price | C4: Annual Price (if offered) | D4: Initiation Fee | E4: Booking Window (days) | F4: Court Discount (%) | G4: Open Play (member price) | H4: Guest Passes / mo | I4: Lesson Discount (%) | J4: League Priority (Y/N) | K4: Cancellation Window (hrs) | L4: Freeze Months / yr | M4: Notes
A5: Non‑Member Day Pass | G5: 12 | J5: N | M5: Single‑day access (no advance booking)
A6: Weekday AM (Off‑Peak) | B6: 35 | D6: 0 | E6: 2 | F6: 0.3 | G6: 6 | H6: 0 | I6: 0.1 | J6: N | K6: 12 | L6: 1 | M6: Access M‑F before 12pm; limited booking
A7: Standard | B7: 60 | C7: 689 | D7: 0 | E7: 7 | F7: 0.25 | G7: 8 | H7: 1 | I7: 0.1 | J7: Y | K7: 12 | L7: 1 | M7: Best for 1–3x/week players
A8: Plus | B8: 100 | C8: 999 | D8: 0 | E8: 10 | F8: 0.35 | G8: 6 | H8: 2 | I8: 0.15 | J8: Y | K8: 6 | L8: 2 | M8: Longer booking, more discounts, extra guest passes
A9: Advanced | B9: 140 | C9: 1399 | D9: 0 | E9: 14 | F9: 0.4 | G9: 5 | H9: 4 | I9: 0.2 | J9: Y | K9: 24 | L9: 3 | M9: Highest Non-Founder Tier
A10: Family (3 people) | B10: 179 | C10: 1900 | D10: 0 | E10: 10 | F10: 0.3 | G10: 6 | H10: 2 | I10: 0.15 | J10: Y | K10: 12 | L10: 2 | M10: Addl. family +$25/mo each
A11: Corporate (per seat) | B11: 65 | D11: 0 | E11: 7 | F11: 0.25 | G11: 8 | H11: 0 | I11: 0.1 | J11: Y | K11: 12 | L11: 0 | M11: Requires 10+ seats; pooled billing
A12: Founders (limited) | B12: 119 | C12: 1299 | D12: 0 | E12: 21 | F12: 0.4 | G12: 4 | H12: 4 | I12: 0.2 | J12: Y | K12: 24 | L12: 3 | M12: Limited quantity; merch & early event access (first 100)
A15: Assumptions (Edit)
A16: Total Members | B16: =Assumptions!B16 -> 50
A17: % Monthly vs Annual purchasers (monthly) | B17: 1
A18: Day Pass Price (Non‑Member) | B18: 12
A19: Monthly Day Pass Count (avg) | B19: 220
A20: Churn (monthly, starting point) | B20: 0.04
A21: New Member Adds / Month | B21: 30
A23: Member Distribution by Tier (sums to 100%)
A24: Tier | B24: % of Members
A25: Weekday AM (Off‑Peak) | B25: 0.08
A26: Standard | B26: 0.44
A27: Plus | B27: 0.21
A28: Advanced | B28: 0.12
A29: Family (3 people) | B29: 0.12
A30: Corporate (per seat) | B30: 0
A31: Founders (limited) | B31: 0.03
A34: Calculated Members & Revenue
A35: Tier | B35: Members (calc) | C35: Monthly Price | D35: Annual Price | E35: % Monthly Buyers | F35: Monthly MRR | G35: Annual MRR (monthly equivalent)
A36: Weekday AM (Off‑Peak) | B36: =$B$16*$B$25 -> 4 | C36: =VLOOKUP(A36, $A$5:$M$12, 2, FALSE) -> 35 | D36: =VLOOKUP(A36, $A$5:$M$12, 3, FALSE) -> 0 | E36: =$B$17 -> 1 | F36: =B36*E36*C36 -> 140 | G36: =B36*(1-E36)*(D36/12) -> 0
A37: Standard | B37: =$B$16*$B$26 -> 22 | C37: =VLOOKUP(A37, $A$5:$M$12, 2, FALSE) -> 60 | D37: =VLOOKUP(A37, $A$5:$M$12, 3, FALSE) -> 689 | E37: =$B$17 -> 1 | F37: =B37*E37*C37 -> 1320 | G37: =B37*(1-E37)*(D37/12) -> 0
A38: Plus | B38: =$B$16*$B$27 -> 10.5 | C38: =VLOOKUP(A38, $A$5:$M$12, 2, FALSE) -> 100 | D38: =VLOOKUP(A38, $A$5:$M$12, 3, FALSE) -> 999 | E38: =$B$17 -> 1 | F38: =B38*E38*C38 -> 1050 | G38: =B38*(1-E38)*(D38/12) -> 0
A39: Advanced | B39: =$B$16*$B$28 -> 6 | C39: =VLOOKUP(A39, $A$5:$M$12, 2, FALSE) -> 140 | D39: =VLOOKUP(A39, $A$5:$M$12, 3, FALSE) -> 1399 | E39: =$B$17 -> 1 | F39: =B39*E39*C39 -> 840 | G39: =B39*(1-E39)*(D39/12) -> 0
A40: Family (3 people) | B40: =$B$16*$B$29 -> 6 | C40: =VLOOKUP(A40, $A$5:$M$12, 2, FALSE) -> 179 | D40: =VLOOKUP(A40, $A$5:$M$12, 3, FALSE) -> 1900 | E40: =$B$17 -> 1 | F40: =B40*E40*C40 -> 1074 | G40: =B40*(1-E40)*(D40/12) -> 0
A41: Corporate (per seat) | B41: =$B$16*$B$30 -> 0 | C41: =VLOOKUP(A41, $A$5:$M$12, 2, FALSE) -> 65 | D41: =VLOOKUP(A41, $A$5:$M$12, 3, FALSE) -> 0 | E41: =$B$17 -> 1 | F41: =B41*E41*C41 -> 0 | G41: =B41*(1-E41)*(D41/12) -> 0
A42: Founders (limited) | B42: =$B$16*$B$31 -> 1.5 | C42: =VLOOKUP(A42, $A$5:$M$12, 2, FALSE) -> 119 | D42: =VLOOKUP(A42, $A$5:$M$12, 3, FALSE) -> 1299 | E42: =$B$17 -> 1 | F42: =B42*E42*C42 -> 178.5 | G42: =B42*(1-E42)*(D42/12) -> 0
A43: TOTAL | B43: =SUM(B35:B42) -> 50 | F43: =SUM(F35:F42) -> 4602.5 | G43: =SUM(G35:G42) -> 0
A45: Non‑Member Day Pass Revenue
A46: Price | B46: Passes / Month | C46: Revenue / Month
A47: =$B$18 -> 12 | B47: =$B$19 -> 220 | C47: =A47*B47 -> 2640
A50: KPIs (auto)
...

Sheet Court Revenue (36m)
A1: Membership-Driven Court Revenue Model – 36 months (Monthly) – v4 (Seasonality)
A2: Seasonality Index scales demand for member & non-member reservations and open play.
A4: INPUTS – Facility & Schedule | E4: INPUTS – Utilization Baselines (Members) | H4: SEASONALITY – Monthly Index
A5: Courts (count) | B5: =Assumptions!B7 -> 8 | E5: Baseline utilization – Peak (weekday) – Members | F5: 0.75 | H5: M1 | I5: 2
A6: Days open per week | B6: =Assumptions!B8 -> 7 | E6: Baseline utilization – Off-peak (weekday) – Members | F6: 0.4 | H6: M2 | I6: 1.5
A7: Hours open per day | B7: 14 | E7: Baseline utilization – Peak (weekend) – Members | F7: 0.85 | H7: M3 | I7: 1.5
A8: Peak hours share of day | B8: =(B7-4)/B7 -> 0.71428571 | E8: Baseline utilization – Off-peak (weekend) – Members | F8: 0.5 | H8: M4 | I8: 1.2
A9: Weekend share of days | B9: 0.28571429 | H9: M5 | I9: 1
A10: Reservation share of total court time (vs open play) | B10: 0.25 | H10: M6 | I10: 0.8
A11: INPUTS – Pricing | E11: INPUTS – Policy & Behavior (Members) | H11: M7 | I11: 0.8
A12: Peak rate – Non-member ($/court-hr) | B12: =Assumptions!B13 -> 40 | E12: No-show rate (paid/no-refund portion) | F12: 0.05 | H12: M8 | I12: 0.8
A13: Off-peak rate – Non-member ($/court-hr) | B13: =Assumptions!B14 -> 30 | E13: Member booking share of reservations (target) | F13: 0.7 | H13: M9 | I13: 1
A14: Member discount on court rate | B14: 0.25 | E14: Booking window uplift (members vs non) | F14: 0.05 | H14: M10 | I14: 1.2
A15: Open Play price – Member ($/session) | B15: 5 | H15: M11 | I15: 1.5
A16: Open Play price – Non-member ($/session) | B16: 8 | H16: M12 | I16: 2
A17: Open Play session length (min) | B17: 60 | H17: Notes:
A19: INPUTS – Membership Growth (drives demand) | E19: INPUTS – Non-member Reservation Demand
A20: Starting Members (Month 1) | B20: =Assumptions!B16 -> 50 | E20: Baseline utilization – Peak (weekday) – Non-members | F20: 0.5
A21: Monthly Member Growth Rate (%) | B21: =Assumptions!B18 -> 0.05 | E21: Baseline utilization – Off-peak (weekday) – Non-members | F21: 0.4
A22: Max Member Capacity (optional) | B22: 1000 | E22: Baseline utilization – Peak (weekend) – Non-members | F22: 0.5
A23: % Members who reserve monthly | B23: 0.5 | E23: Baseline utilization – Off-peak (weekend) – Non-members | F23: 0.4
A24: Avg reservations per reserving member / month | B24: 2 | E24: Marketing uplift – Non-members (reservations) | F24: 0.1
A25: Avg reservation duration (min) | B25: 60 | E25: Non-member reservation cap (% of reservation capacity) | F25: 1
A26: Avg open-play sessions / member / month | B26: 12
A27: Open Play players per court capacity (per hour) | B27: 6
A29: HELPERS | E29: Blended Utilization
A30: Total Court Hours / month | B30: =B7*B5*4.33*B6 -> 3394.72 | E30: Blended Peak Utilization – Members | F30: =(1-B8)*F5 + B8*F7 -> 0.82142857
A31: Peak Hours / month | B31: =B30*B8 -> 2424.8 | E31: Blended Off-Peak Utilization – Members | F31: =(1-B8)*F6 + B8*F8 -> 0.47142857
A32: Off-Peak Hours / month | B32: =B30*(1-B8) -> 969.92
A33: Open Play Hours Share | B33: =(1-B10) -> 0.75 | E33: Blended Utilization – Non-members
E34: Blended Peak Utilization – Non-members | F34: =(1-B8)*F20 + B8*F22 -> 0.5
E35: Blended Off-Peak Utilization – Non-members | F35: =(1-B8)*F21 + B8*F23 -> 0.4
E37: Reservation Capacity (attended hours cap)
E38: Reservation Capacity Hours / month | F38: =(B31*F30 + B32*F31)*B10 -> 612.262
A39: Reservation Duration (hours) | B39: =B25/60 -> 1
A40: Open Play Session Length (hours) | B40: =B17/60 -> 1 | E40: Reservation Rates (blended)
E41: Blended Non-member Reservation Rate ($/hr) | F41: =(B12*B31 + B13*B32)/(B31+B32) -> 37.142857
E42: Blended Member Reservation Rate ($/hr) | F42: =F41*(1-B14) -> 27.857143
A44: Month | B44: Seasonality Index | C44: Members | D44: Member Reservation Hours (raw) | E44: Member Reservation Hours (capped) | F44: Non-member Reservation Demand Hours | G44: Non-member Reservation Hours (actual) | H44: Avg Reservation Rate ($/hr) | I44: Reservation Revenue (attended) | J44: No-show Revenue | K44: Member Open Play Hours (raw) | L44: Member Open Play Hours (capped) | M44: Member Open Play Sessions | N44: Member Open Play Revenue | O44: Non-member Open Play Hours | P44: Non-member Open Play Sessions | Q44: Non-member Open Play Revenue | R44: TOTAL Court Revenue ($/mo)
A45: M1 | B45: =INDEX($I$5:$I$16, 1+MOD(1-1,12)) -> 2 | C45: =MIN(B20,$B$22) -> 50 | D45: =C45*$B$23*$B$24*$B$39*B45 -> 100 | E45: =MIN(D45, $F$38) -> 100 | F45: =(($B$31*$F$34*$B$10) + ($B$32*$F$35*$B$10))*(1+$F$24)*B45 -> 880.2024 | G45: =MIN(F45, MAX($F$38-E45,0), $F$25*$F$38) -> 512.262 | H45: =IFERROR(($F$42*E45 + $F$41*G45)/(E45+G45),0) -> 35.626233 | I45: =(E45+G45)*H45 -> 21812.589 | J45: =H45*(E45+G45)*$F$12 -> 1090.6294 | K45: =C45*$B$26*$B$40*B45 -> 1200 | L45: =MIN(K45, $B$30*(1-$B$10)) -> 1200 | M45: =IFERROR(L45/$B$40,0) -> 1200 | N45: =M45*$B$15 -> 6000 | O45: =MAX($B$30*(1-$B$10)-L45,0) -> 1346.04 | P45: =IFERROR(O45/$B$40,0) -> 1346.04 | Q45: =P45*$B$16 -> 10768.32 | R45: =I45+J45+N45+Q45 -> 39671.538
...

Sheet Revenue Model
A1: Monthly Revenue Model (first 36 months)
A2: Uses court utilization + pricing + memberships + lessons + leagues + retail/cafe.
A4: Month | B4: Court Revenue | C4: Members | D4: Memberships | E4: Lessons | F4: Leagues | G4: Retail | H4: Cafe | I4: Total Revenue
A5: 1 | B5: ='Court Revenue (36m)'!R45 -> 39671.538 | C5: =Assumptions!B16 -> 50 | D5: =C5*Assumptions!$B$17 -> 4602.5 | E5: =Assumptions!$B$19*4.33*Assumptions!$B$20 -> 6754.8 | F5: =(Assumptions!$B$21*Assumptions!$B$22*Assumptions!$B$23)/12 -> 1000 | G5: =Assumptions!$B$24 -> 3000 | H5: =Assumptions!$B$26 -> 5000 | I5: =SUM(B5:H5) -> 60078.838
A6: 2 | B6: ='Court Revenue (36m)'!R46 -> 40643.726 | C6: =(1+Assumptions!$B$18)*C5 -> 52.5 | D6: =C6*Assumptions!$B$17 -> 4832.625 | E6: =Assumptions!$B$19*4.33*Assumptions!$B$20 -> 6754.8 | F6: =(Assumptions!$B$21*Assumptions!$B$22*Assumptions!$B$23)/12 -> 1000 | G6: =Assumptions!$B$24 -> 3000 | H6: =Assumptions!$B$26 -> 5000 | I6: =SUM(B6:H6) -> 61283.651
A7: 3 | B7: ='Court Revenue (36m)'!R47 -> 35802.215 | C7: =(1+Assumptions!$B$18)*C6 -> 55.125 | D7: =C7*Assumptions!$B$17 -> 5074.2562 | E7: =Assumptions!$B$19*4.33*Assumptions!$B$20 -> 6754.8 | F7: =(Assumptions!$B$21*Assumptions!$B$22*Assumptions!$B$23)/12 -> 1000 | G7: =Assumptions!$B$24 -> 3000 | H7: =Assumptions!$B$26 -> 5000 | I7: =SUM(B7:H7) -> 56686.396
A8: 4 | B8: ='Court Revenue (36m)'!R48 -> 35358.568 | C8: =(1+Assumptions!$B$18)*C7 -> 57.88125 | D8: =C8*Assumptions!$B$17 -> 5327.9691 | E8: =Assumptions!$B$19*4.33*Assumptions!$B$20 -> 6754.8 | F8: =(Assumptions!$B$21*Assumptions!$B$22*Assumptions!$B$23)/12 -> 1000 | G8: =Assumptions!$B$24 -> 3000 | H8: =Assumptions!$B$26 -> 5000 | I8: =SUM(B8:H8) -> 56499.218
A9: 5 | B9: ='Court Revenue (36m)'!R49 -> 31671.825 | C9: =(1+Assumptions!$B$18)*C8 -> 60.775313 | D9: =C9*Assumptions!$B$17 -> 5594.3675 | E9: =Assumptions!$B$19*4.33*Assumptions!$B$20 -> 6754.8 | F9: =(Assumptions!$B$21*Assumptions!$B$22*Assumptions!$B$23)/12 -> 1000 | G9: =Assumptions!$B$24 -> 3000 | H9: =Assumptions!$B$26 -> 5000 | I9: =SUM(B9:H9) -> 53081.768
A10: 6 | B10: ='Court Revenue (36m)'!R50 -> 27954.607 | C10: =(1+Assumptions!$B$18)*C9 -> 63.814078 | D10: =C10*Assumptions!$B$17 -> 5874.0859 | E10: =Assumptions!$B$19*4.33*Assumptions!$B$20 -> 6754.8 | F10: =(Assumptions!$B$21*Assumptions!$B$22*Assumptions!$B$23)/12 -> 1000 | G10: =Assumptions!$B$24 -> 3000 | H10: =Assumptions!$B$26 -> 5000 | I10: =SUM(B10:H10) -> 49647.307
A11: 7 | B11: ='Court Revenue (36m)'!R51 -> 28029.269 | C11: =(1+Assumptions!$B$18)*C10 -> 67.004782 | D11: =C11*Assumptions!$B$17 -> 6167.7902 | E11: =Assumptions!$B$19*4.33*Assumptions!$B$20 -> 6754.8 | F11: =(Assumptions!$B$21*Assumptions!$B$22*Assumptions!$B$23)/12 -> 1000 | G11: =Assumptions!$B$24 -> 3000 | H11: =Assumptions!$B$26 -> 5000 | I11: =SUM(B11:H11) -> 50018.864
A12: 8 | B12: ='Court Revenue (36m)'!R52 -> 28107.665 | C12: =(1+Assumptions!$B$18)*C11 -> 70.355021 | D12: =C12*Assumptions!$B$17 -> 6476.1797 | E12: =Assumptions!$B$19*4.33*Assumptions!$B$20 -> 6754.8 | F12: =(Assumptions!$B$21*Assumptions!$B$22*Assumptions!$B$23)/12 -> 1000 | G12: =Assumptions!$B$24 -> 3000 | H12: =Assumptions!$B$26 -> 5000 | I12: =SUM(B12:H12) -> 50409
A13: 9 | B13: ='Court Revenue (36m)'!R53 -> 32054.925 | C13: =(1+Assumptions!$B$18)*C12 -> 73.872772 | D13: =C13*Assumptions!$B$17 -> 6799.9887 | E13: =Assumptions!$B$19*4.33*Assumptions!$B$20 -> 6754.8 | F13: =(Assumptions!$B$21*Assumptions!$B$22*Assumptions!$B$23)/12 -> 1000 | G13: =Assumptions!$B$24 -> 3000 | H13: =Assumptions!$B$26 -> 5000 | I13: =SUM(B13:H13) -> 54683.587
A14: 10 | B14: ='Court Revenue (36m)'!R54 -> 35700.891 | C14: =(1+Assumptions!$B$18)*C13 -> 77.566411 | D14: =C14*Assumptions!$B$17 -> 7139.9881 | E14: =Assumptions!$B$19*4.33*Assumptions!$B$20 -> 6754.8 | F14: =(Assumptions!$B$21*Assumptions!$B$22*Assumptions!$B$23)/12 -> 1000 | G14: =Assumptions!$B$24 -> 3000 | H14: =Assumptions!$B$26 -> 5000 | I14: =SUM(B14:H14) -> 58673.246
A15: 11 | B15: ='Court Revenue (36m)'!R55 -> 35417.289 | C15: =(1+Assumptions!$B$18)*C14 -> 81.444731 | D15: =C15*Assumptions!$B$17 -> 7496.9875 | E15: =Assumptions!$B$19*4.33*Assumptions!$B$20 -> 6754.8 | F15: =(Assumptions!$B$21*Assumptions!$B$22*Assumptions!$B$23)/12 -> 1000 | G15: =Assumptions!$B$24 -> 3000 | H15: =Assumptions!$B$26 -> 5000 | I15: =SUM(B15:H15) -> 58750.521
A16: 12 | B16: ='Court Revenue (36m)'!R56 -> 34940.837 | C16: =(1+Assumptions!$B$18)*C15 -> 85.516968 | D16: =C16*Assumptions!$B$17 -> 7871.8369 | E16: =Assumptions!$B$19*4.33*Assumptions!$B$20 -> 6754.8 | F16: =(Assumptions!$B$21*Assumptions!$B$22*Assumptions!$B$23)/12 -> 1000 | G16: =Assumptions!$B$24 -> 3000 | H16: =Assumptions!$B$26 -> 5000 | I16: =SUM(B16:H16) -> 58652.991
A17: 13 | B17: ='Court Revenue (36m)'!R57 -> 34857.458 | C17: =(1+Assumptions!$B$18)*C16 -> 89.792816 | D17: =C17*Assumptions!$B$17 -> 8265.4287 | E17: =Assumptions!$B$19*4.33*Assumptions!$B$20 -> 6754.8 | F17: =(Assumptions!$B$21*Assumptions!$B$22*Assumptions!$B$23)/12 -> 1000 | G17: =Assumptions!$B$24 -> 3000 | H17: =Assumptions!$B$26 -> 5000 | I17: =SUM(B17:H17) -> 58967.48
... A52: 48 | B52: ='Court Revenue (36m)'!R92 -> 35424.064 | C52: =(1+Assumptions!$B$18)*C51 -> 495.29855 | D52: =C52*Assumptions!$B$17 -> 45592.232 | E52: =Assumptions!$B$19*4.33*Assumptions!$B$20 -> 6754.8 | F52: =(Assumptions!$B$21*Assumptions!$B$22*Assumptions!$B$23)/12 -> 1000 | G52: =Assumptions!$B$24 -> 3000 | H52: =Assumptions!$B$26 -> 5000 | I52: =SUM(B52:H52) -> 97266.394

Sheet Staffing & Payroll
A1: Weekly Staffing Plan (links to Assumptions)
A3: Role | B3: Hours/Week | C3: Wage $/hr | D3: Weekly Payroll | E3: Monthly Payroll (≈4.33x)
A4: Front Desk | B4: =Assumptions!B28 -> 196 | C4: =Assumptions!B29 -> 18 | D4: =B4*C4 -> 3528 | E4: =D4*4.33 -> 15276.24
A5: Coaches | B5: =Assumptions!B30 -> 40 | C5: =Assumptions!B31 -> 30 | D5: =B5*C5 -> 1200 | E5: =D5*4.33 -> 5196
A6: Cafe | B6: =Assumptions!B32 -> 60 | C6: =Assumptions!B33 -> 17 | D6: =B6*C6 -> 1020 | E6: =D6*4.33 -> 4416.6
A7: Totals | D7: =SUM(D4:D6) -> 5748 | E7: =SUM(E4:E6) -> 24888.84

Sheet OPEX
A1: Operating Expenses (Monthly)
A2: Expected OPEX
A3: Category | B3: Amount ($/mo) | D3: COGS Helpers
A4: Base Rent | B4: 30000 | D4: Retail COGS $/mo | E4: =Assumptions!B24*Assumptions!B25 -> 1650
A5: Utilities | B5: =Assumptions!B35 -> 6000 | D5: Cafe COGS $/mo | E5: =Assumptions!B26*Assumptions!B27 -> 2250
A6: Insurance | B6: 2000 | D6: Total COGS $/mo | E6: =E4+E5 -> 3900
A7: Marketing | B7: =Assumptions!B37 -> 4000
A8: Software | B8: =Assumptions!B38 -> 2000
A9: Cleaning & Supplies | B9: 2200
A10: Misc. Opex | B10: =Assumptions!B40 -> 2000
A11: Total OPEX (incl. rent) | B11: =SUM(B4:B10) -> 48200

Sheet P&L (36m)
A1: Profit & Loss – Monthly (36 months)
A2: Predicted P&L
A3: Month | B3: Total Revenue | C3: COGS | D3: Payroll | E3: OPEX | F3: EBITDA | G3: Interest | H3: EBT
A4: 1 | B4: ='Revenue Model'!I5 -> 60078.838 | C4: =OPEX!E6 -> 3900 | D4: ='Staffing & Payroll'!E7 -> 24888.84 | E4: =OPEX!B11 -> 48200 | F4: =B4-C4-D4-E4 -> -16910.002 | G4: =Financing!D4 -> 15833.333 | H4: =F4-G4 -> -32743.335
A5: 2 | B5: ='Revenue Model'!I6 -> 61283.651 | C5: =OPEX!E6 -> 3900 | D5: ='Staffing & Payroll'!E7 -> 24888.84 | E5: =OPEX!B11 -> 48200 | F5: =B5-C5-D5-E5 -> -15705.189 | G5: =Financing!D5 -> 15753.801 | H5: =F4-G4 -> -32743.335
A6: 3 | B6: ='Revenue Model'!I7 -> 56686.396 | C6: =OPEX!E6 -> 3900 | D6: ='Staffing & Payroll'!E7 -> 24888.84 | E6: =OPEX!B11 -> 48200 | F6: =B6-C6-D6-E6 -> -20302.444 | G6: =Financing!D6 -> 15673.639 | H6: =F5-G5 -> -31458.991
A7: 4 | B7: ='Revenue Model'!I8 -> 56499.218 | C7: =OPEX!E6 -> 3900 | D7: ='Staffing & Payroll'!E7 -> 24888.84 | E7: =OPEX!B11 -> 48200 | F7: =B7-C7-D7-E7 -> -20489.622 | G7: =Financing!D7 -> 15592.843 | H7: =F6-G6 -> -35976.083
A8: 5 | B8: ='Revenue Model'!I9 -> 53081.768 | C8: =OPEX!E6 -> 3900 | D8: ='Staffing & Payroll'!E7 -> 24888.84 | E8: =OPEX!B11 -> 48200 | F8: =B8-C8-D8-E8 -> -23907.072 | G8: =Financing!D8 -> 15511.407 | H8: =F7-G7 -> -36082.464
A9: 6 | B9: ='Revenue Model'!I10 -> 49647.307 | C9: =OPEX!E6 -> 3900 | D9: ='Staffing & Payroll'!E7 -> 24888.84 | E9: =OPEX!B11 -> 48200 | F9: =B9-C9-D9-E9 -> -27341.533 | G9: =Financing!D9 -> 15429.326 | H9: =F8-G8 -> -39418.479
A10: 7 | B10: ='Revenue Model'!I11 -> 50018.864 | C10: =OPEX!E6 -> 3900 | D10: ='Staffing & Payroll'!E7 -> 24888.84 | E10: =OPEX!B11 -> 48200 | F10: =B10-C10-D10-E10 -> -26969.976 | G10: =Financing!D10 -> 15346.595 | H10: =F9-G9 -> -42770.859
A11: 8 | B11: ='Revenue Model'!I12 -> 50409 | C11: =OPEX!E6 -> 3900 | D11: ='Staffing & Payroll'!E7 -> 24888.84 | E11: =OPEX!B11 -> 48200 | F11: =B11-C11-D11-E11 -> -26579.84 | G11: =Financing!D11 -> 15263.21 | H11: =F10-G10 -> -42316.571
A12: 9 | B12: ='Revenue Model'!I13 -> 54683.587 | C12: =OPEX!E6 -> 3900 | D12: ='Staffing & Payroll'!E7 -> 24888.84 | E12: =OPEX!B11 -> 48200 | F12: =B12-C12-D12-E12 -> -22305.253 | G12: =Financing!D12 -> 15179.164 | H12: =F11-G11 -> -41843.05
A13: 10 | B13: ='Revenue Model'!I14 -> 58673.246 | C13: =OPEX!E6 -> 3900 | D13: ='Staffing & Payroll'!E7 -> 24888.84 | E13: =OPEX!B11 -> 48200 | F13: =B13-C13-D13-E13 -> -18315.594 | G13: =Financing!D13 -> 15094.453 | H13: =F12-G12 -> -37484.417
A14: 11 | B14: ='Revenue Model'!I15 -> 58750.521 | C14: =OPEX!E6 -> 3900 | D14: ='Staffing & Payroll'!E7 -> 24888.84 | E14: =OPEX!B11 -> 48200 | F14: =B14-C14-D14-E14 -> -18238.319 | G14: =Financing!D14 -> 15009.071 | H14: =F13-G13 -> -33410.047
A15: 12 | B15: ='Revenue Model'!I16 -> 58652.991 | C15: =OPEX!E6 -> 3900 | D15: ='Staffing & Payroll'!E7 -> 24888.84 | E15: =OPEX!B11 -> 48200 | F15: =B15-C15-D15-E15 -> -18335.849 | G15: =Financing!D15 -> 14923.013 | H15: =F14-G14 -> -33247.39
A16: 13 | B16: ='Revenue Model'!I17 -> 58967.48 | C16: =OPEX!E6 -> 3900 | D16: ='Staffing & Payroll'!E7 -> 24888.84 | E16: =OPEX!B11 -> 48200 | F16: =B16-C16-D16-E16 -> -18021.36 | G16: =Financing!D16 -> 14836.274 | H16: =F15-G15 -> -33258.862
A17: 14 | B17: ='Revenue Model'!I18 -> 59757.32 | C17: =OPEX!E6 -> 3900 | D17: ='Staffing & Payroll'!E7 -> 24888.84 | E17: =OPEX!B11 -> 48200 | F17: =B17-C17-D17-E17 -> -17231.52 | G17: =Financing!D17 -> 14748.849 | H17: =F16-G16 -> -32857.635
A18: 15 | B18: ='Revenue Model'!I19 -> 60127.025 | C18: =OPEX!E6 -> 3900 | D18: ='Staffing & Payroll'!E7 -> 24888.84 | E18: =OPEX!B11 -> 48200 | F18: =B18-C18-D18-E18 -> -16861.815 | G18: =Financing!D18 -> 14660.731 | H18: =F17-G17 -> -31980.369
A19: 16 | B19: ='Revenue Model'!I20 -> 60819.258 | C19: =OPEX!E6 -> 3900 | D19: ='Staffing & Payroll'!E7 -> 24888.84 | E19: =OPEX!B11 -> 48200 | F19: =B19-C19-D19-E19 -> -16169.582 | G19: =Financing!D19 -> 14571.916 | H19: =F18-G18 -> -31522.546
A20: 17 | B20: ='Revenue Model'!I21 -> 58997.225 | C20: =OPEX!E6 -> 3900 | D20: ='Staffing & Payroll'!E7 -> 24888.84 | E20: =OPEX!B11 -> 48200 | F20: =B20-C20-D20-E20 -> -17991.615 | G20: =Financing!D20 -> 14482.397 | H20: =F19-G19 -> -30741.497
A21: 18 | B21: ='Revenue Model'!I22 -> 55561.434 | C21: =OPEX!E6 -> 3900 | D21: ='Staffing & Payroll'!E7 -> 24888.84 | E21: =OPEX!B11 -> 48200 | F21: =B21-C21-D21-E21 -> -21427.406 | G21: =Financing!D21 -> 14392.17 | H21: =F20-G20 -> -32474.012
A22: 19 | B22: ='Revenue Model'!I23 -> 56228.698 | C22: =OPEX!E6 -> 3900 | D22: ='Staffing & Payroll'!E7 -> 24888.84 | E22: =OPEX!B11 -> 48200 | F22: =B22-C22-D22-E22 -> -20760.142 | G22: =Financing!D22 -> 14301.229 | H22: =F21-G21 -> -35819.576
A23: 20 | B23: ='Revenue Model'!I24 -> 56929.325 | C23: =OPEX!E6 -> 3900 | D23: ='Staffing & Payroll'!E7 -> 24888.84 | E23: =OPEX!B11 -> 48200 | F23: =B23-C23-D23-E23 -> -20059.515 | G23: =Financing!D23 -> 14209.567 | H23: =F22-G22 -> -35061.371
A24: 21 | B24: ='Revenue Model'!I25 -> 61873.862 | C24: =OPEX!E6 -> 3900 | D24: ='Staffing & Payroll'!E7 -> 24888.84 | E24: =OPEX!B11 -> 48200 | F24: =B24-C24-D24-E24 -> -15114.978 | G24: =Financing!D24 -> 14117.18 | H24: =F23-G23 -> -34269.082
A25: 22 | B25: ='Revenue Model'!I26 -> 63695.121 | C25: =OPEX!E6 -> 3900 | D25: ='Staffing & Payroll'!E7 -> 24888.84 | E25: =OPEX!B11 -> 48200 | F25: =B25-C25-D25-E25 -> -13293.719 | G25: =Financing!D25 -> 14024.062 | H25: =F24-G24 -> -29232.158
A26: 23 | B26: ='Revenue Model'!I27 -> 63833.897 | C26: =OPEX!E6 -> 3900 | D26: ='Staffing & Payroll'!E7 -> 24888.84 | E26: =OPEX!B11 -> 48200 | F26: =B26-C26-D26-E26 -> -13154.943 | G26: =Financing!D26 -> 13930.206 | H26: =F25-G25 -> -27317.781
A27: 24 | B27: ='Revenue Model'!I28 -> 63658.747 | C27: =OPEX!E6 -> 3900 | D27: ='Staffing & Payroll'!E7 -> 24888.84 | E27: =OPEX!B11 -> 48200 | F27: =B27-C27-D27-E27 -> -13330.093 | G27: =Financing!D27 -> 13835.607 | H27: =F26-G26 -> -27085.149
A28: 25 | B28: ='Revenue Model'!I29 -> 64223.523 | C28: =OPEX!E6 -> 3900 | D28: ='Staffing & Payroll'!E7 -> 24888.84 | E28: =OPEX!B11 -> 48200 | F28: =B28-C28-D28-E28 -> -12765.317 | G28: =Financing!D28 -> 13740.26 | H28: =F27-G27 -> -27165.701
A29: 26 | B29: ='Revenue Model'!I30 -> 65641.962 | C29: =OPEX!E6 -> 3900 | D29: ='Staffing & Payroll'!E7 -> 24888.84 | E29: =OPEX!B11 -> 48200 | F29: =B29-C29-D29-E29 -> -11346.878 | G29: =Financing!D29 -> 13644.157 | H29: =F28-G28 -> -26505.577
A30: 27 | B30: ='Revenue Model'!I31 -> 66305.9 | C30: =OPEX!E6 -> 3900 | D30: ='Staffing & Payroll'!E7 -> 24888.84 | E30: =OPEX!B11 -> 48200 | F30: =B30-C30-D30-E30 -> -10682.94 | G30: =Financing!D30 -> 13547.294 | H30: =F29-G29 -> -24991.035
A31: 28 | B31: ='Revenue Model'!I32 -> 67549.052 | C31: =OPEX!E6 -> 3900 | D31: ='Staffing & Payroll'!E7 -> 24888.84 | E31: =OPEX!B11 -> 48200 | F31: =B31-C31-D31-E31 -> -9439.7884 | G31: =Financing!D31 -> 13449.664 | H31: =F30-G30 -> -24230.235
A32: 29 | B32: ='Revenue Model'!I33 -> 68690.556 | C32: =OPEX!E6 -> 3900 | D32: ='Staffing & Payroll'!E7 -> 24888.84 | E32: =OPEX!B11 -> 48200 | F32: =B32-C32-D32-E32 -> -8298.2841 | G32: =Financing!D32 -> 13351.261 | H32: =F31-G31 -> -22889.453
A33: 30 | B33: ='Revenue Model'!I34 -> 66182.357 | C33: =OPEX!E6 -> 3900 | D33: ='Staffing & Payroll'!E7 -> 24888.84 | E33: =OPEX!B11 -> 48200 | F33: =B33-C33-D33-E33 -> -10806.483 | G33: =Financing!D33 -> 13252.079 | H33: =F32-G32 -> -21649.545
A34: 31 | B34: ='Revenue Model'!I35 -> 67380.667 | C34: =OPEX!E6 -> 3900 | D34: ='Staffing & Payroll'!E7 -> 24888.84 | E34: =OPEX!B11 -> 48200 | F34: =B34-C34-D34-E34 -> -9608.1731 | G34: =Financing!D34 -> 13152.112 | H34: =F33-G33 -> -24058.562
A35: 32 | B35: ='Revenue Model'!I36 -> 68638.892 | C35: =OPEX!E6 -> 3900 | D35: ='Staffing & Payroll'!E7 -> 24888.84 | E35: =OPEX!B11 -> 48200 | F35: =B35-C35-D35-E35 -> -8349.9476 | G35: =Financing!D35 -> 13051.353 | H35: =F34-G34 -> -22760.285
A36: 33 | B36: ='Revenue Model'!I37 -> 72209.199 | C36: =OPEX!E6 -> 3900 | D36: ='Staffing & Payroll'!E7 -> 24888.84 | E36: =OPEX!B11 -> 48200 | F36: =B36-C36-D36-E36 -> -4779.6408 | G36: =Financing!D36 -> 12949.797 | H36: =F35-G35 -> -21401.301
A37: 34 | B37: ='Revenue Model'!I38 -> 72713.687 | C37: =OPEX!E6 -> 3900 | D37: ='Staffing & Payroll'!E7 -> 24888.84 | E37: =OPEX!B11 -> 48200 | F37: =B37-C37-D37-E37 -> -4275.1526 | G37: =Financing!D37 -> 12847.437 | H37: =F36-G36 -> -17729.438
A38: 35 | B38: ='Revenue Model'!I39 -> 72962.909 | C38: =OPEX!E6 -> 3900 | D38: ='Staffing & Payroll'!E7 -> 24888.84 | E38: =OPEX!B11 -> 48200 | F38: =B38-C38-D38-E38 -> -4025.9313 | G38: =Financing!D38 -> 12744.266 | H38: =F37-G37 -> -17122.59
A39: 36 | B39: ='Revenue Model'!I40 -> 72648.365 | C39: =OPEX!E6 -> 3900 | D39: ='Staffing & Payroll'!E7 -> 24888.84 | E39: =OPEX!B11 -> 48200 | F39: =B39-C39-D39-E39 -> -4340.4755 | G39: =Financing!D39 -> 12640.279 | H39: =F38-G38 -> -16770.198
A40: 37 | B40: ='Revenue Model'!I41 -> 75074.377 | C40: =OPEX!E6 -> 3900 | D40: ='Staffing & Payroll'!E7 -> 24888.84 | E40: =OPEX!B11 -> 48200 | F40: =B40-C40-D40-E40 -> -1914.463 | G40: =Financing!D40 -> 12535.468 | H40: =F39-G39 -> -16980.754
...

Sheet Cash Flow
A1: Cash Flow – Monthly (36 months)
A2: Predicted Cash Flow
A3: Month | B3: EBITDA | C3: Interest | D3: Debt Service (PMT) | E3: Principal | F3: CapEx | G3: Net Cash Flow | H3: Cash Balance
A4: 1 | B4: ='P&L (36m)'!F4 -> -16910.002 | C4: ='P&L (36m)'!G4 -> 15833.333 | D4: =MonthlyDebtService -> 25879.512 | E4: =D4-C4 -> 10046.178 | F4: ='CapEx & Sources'!E22 -> 799260 | G4: =B4-C4-F4 -> -832003.34 | H4: =Assumptions!$B$41 + Financing!$B$4 + ABS('CapEx & Sources'!$H$5) -F4 +G4 -> 1569476.7
A5: 2 | B5: ='P&L (36m)'!F4 -> -16910.002 | C5: ='P&L (36m)'!G4 -> 15833.333 | D5: =MonthlyDebtService -> 25879.512 | E5: =D5-C5 -> 10046.178 | F5: 0 | G5: =B5-C5-F5 -> -32743.335 | H5: =H4+G5 -> 1536733.3
A6: 3 | B6: ='P&L (36m)'!F5 -> -15705.189 | C6: ='P&L (36m)'!G5 -> 15753.801 | D6: =MonthlyDebtService -> 25879.512 | E6: =D6-C6 -> 10125.71 | F6: 0 | G6: =B6-C6-F6 -> -31458.991 | H6: =H5+G6 -> 1505274.3
A7: 4 | B7: ='P&L (36m)'!F6 -> -20302.444 | C7: ='P&L (36m)'!G6 -> 15673.639 | D7: =MonthlyDebtService -> 25879.512 | E7: =D7-C7 -> 10205.872 | F7: 0 | G7: =B7-C7-F7 -> -35976.083 | H7: =H6+G7 -> 1469298.3
A8: 5 | B8: ='P&L (36m)'!F7 -> -20489.622 | C8: ='P&L (36m)'!G7 -> 15592.843 | D8: =MonthlyDebtService -> 25879.512 | E8: =D8-C8 -> 10286.669 | F8: 0 | G8: =B8-C8-F8 -> -36082.464 | H8: =H7+G8 -> 1433215.8
A9: 6 | B9: ='P&L (36m)'!F8 -> -23907.072 | C9: ='P&L (36m)'!G8 -> 15511.407 | D9: =MonthlyDebtService -> 25879.512 | E9: =D9-C9 -> 10368.105 | F9: 0 | G9: =B9-C9-F9 -> -39418.479 | H9: =H8+G9 -> 1393797.3
A10: 7 | B10: ='P&L (36m)'!F9 -> -27341.533 | C10: ='P&L (36m)'!G9 -> 15429.326 | D10: =MonthlyDebtService -> 25879.512 | E10: =D10-C10 -> 10450.186 | F10: 0 | G10: =B10-C10-F10 -> -42770.859 | H10: =H9+G10 -> 1351026.5
A11: 8 | B11: ='P&L (36m)'!F10 -> -26969.976 | C11: ='P&L (36m)'!G10 -> 15346.595 | D11: =MonthlyDebtService -> 25879.512 | E11: =D11-C11 -> 10532.916 | F11: 0 | G11: =B11-C11-F11 -> -42316.571 | H11: =H10+G11 -> 1308709.9
A12: 9 | B12: ='P&L (36m)'!F11 -> -26579.84 | C12: ='P&L (36m)'!G11 -> 15263.21 | D12: =MonthlyDebtService -> 25879.512 | E12: =D12-C12 -> 10616.302 | F12: 0 | G12: =B12-C12-F12 -> -41843.05 | H12: =H11+G12 -> 1266866.8
A13: 10 | B13: ='P&L (36m)'!F12 -> -22305.253 | C13: ='P&L (36m)'!G12 -> 15179.164 | D13: =MonthlyDebtService -> 25879.512 | E13: =D13-C13 -> 10700.348 | F13: 0 | G13: =B13-C13-F13 -> -37484.417 | H13: =H12+G13 -> 1229382.4
A14: 11 | B14: ='P&L (36m)'!F13 -> -18315.594 | C14: ='P&L (36m)'!G13 -> 15094.453 | D14: =MonthlyDebtService -> 25879.512 | E14: =D14-C14 -> 10785.059 | F14: 0 | G14: =B14-C14-F14 -> -33410.047 | H14: =H13+G14 -> 1195972.4
A15: 12 | B15: ='P&L (36m)'!F14 -> -18238.319 | C15: ='P&L (36m)'!G14 -> 15009.071 | D15: =MonthlyDebtService -> 25879.512 | E15: =D15-C15 -> 10870.44 | F15: 0 | G15: =B15-C15-F15 -> -33247.39 | H15: =H14+G15 -> 1162725
A16: 13 | B16: ='P&L (36m)'!F15 -> -18335.849 | C16: ='P&L (36m)'!G15 -> 14923.013 | D16: =MonthlyDebtService -> 25879.512 | E16: =D16-C16 -> 10956.498 | F16: 0 | G16: =B16-C16-F16 -> -33258.862 | H16: =H15+G16 -> 1129466.1
... A39: 36 | B39: ='P&L (36m)'!F38 -> -4025.9313 | C39: ='P&L (36m)'!G38 -> 12744.266 | D39: =MonthlyDebtService -> 25879.512 | E39: =D39-C39 -> 13135.245 | F39: 0 | G39: =B39-C39-F39 -> -16770.198 | H39: =H38+G39 -> 513831.02
A40: 37 | B40: ='P&L (36m)'!F40 -> -1914.463 | C40: ='P&L (36m)'!G40 -> 12535.468 | D40: =MonthlyDebtService -> 25879.512 | E40: =D40-C40 -> 13344.043 | F40: ='CapEx & Sources'!E58 -> 0 | G40: =B40-C40-F40 -> -14449.931 | H40: =H39+G40 -> 499381.09
A41: 38 | B41: ='P&L (36m)'!F40 -> -1914.463 | C41: ='P&L (36m)'!G40 -> 12535.468 | D41: =MonthlyDebtService -> 25879.512 | E41: =D41-C41 -> 13344.043 | F41: 0 | G41: =B41-C41-F41 -> -14449.931 | H41: =H40+G41 -> 484931.16
A42: 39 | B42: ='P&L (36m)'!F41 -> 5545.6311 | C42: ='P&L (36m)'!G41 -> 12429.828 | D42: =MonthlyDebtService -> 25879.512 | E42: =D42-C42 -> 13449.683 | F42: 0 | G42: =B42-C42-F42 -> -6884.197 | H42: =H41+G42 -> 478046.96
A43: 40 | B43: ='P&L (36m)'!F42 -> 7882.0164 | C43: ='P&L (36m)'!G42 -> 12323.351 | D43: =MonthlyDebtService -> 25879.512 | E43: =D43-C43 -> 13556.16 | F43: 0 | G43: =B43-C43-F43 -> -4441.335 | H43: =H42+G43 -> 473605.63
A44: 41 | B44: ='P&L (36m)'!F43 -> 9972.3024 | C44: ='P&L (36m)'!G43 -> 12216.032 | D44: =MonthlyDebtService -> 25879.512 | E44: =D44-C44 -> 13663.48 | F44: 0 | G44: =B44-C44-F44 -> -2243.7294 | H44: =H43+G44 -> 471361.9
A45: 42 | B45: ='P&L (36m)'!F44 -> 12209.443 | C45: ='P&L (36m)'!G44 -> 12107.863 | D45: =MonthlyDebtService -> 25879.512 | E45: =D45-C45 -> 13771.649 | F45: 0 | G45: =B45-C45-F45 -> 101.58059 | H45: =H44+G45 -> 471463.48
A46: 43 | B46: ='P&L (36m)'!F45 -> 13669.29 | C46: ='P&L (36m)'!G45 -> 11998.837 | D46: =MonthlyDebtService -> 25879.512 | E46: =D46-C46 -> 13880.674 | F46: 0 | G46: =B46-C46-F46 -> 1670.4534 | H46: =H45+G46 -> 473133.93
A47: 44 | B47: ='P&L (36m)'!F46 -> 15202.13 | C47: ='P&L (36m)'!G46 -> 11888.948 | D47: =MonthlyDebtService -> 25879.512 | E47: =D47-C47 -> 13990.563 | F47: 0 | G47: =B47-C47-F47 -> 3313.1817 | H47: =H46+G47 -> 476447.11
A48: 45 | B48: ='P&L (36m)'!F47 -> 15782.309 | C48: ='P&L (36m)'!G47 -> 11778.19 | D48: =MonthlyDebtService -> 25879.512 | E48: =D48-C48 -> 14101.322 | F48: 0 | G48: =B48-C48-F48 -> 4004.119 | H48: =H47+G48 -> 480451.23
A49: 46 | B49: ='P&L (36m)'!F48 -> 16340.031 | C49: ='P&L (36m)'!G48 -> 11666.554 | D49: =MonthlyDebtService -> 25879.512 | E49: =D49-C49 -> 14212.957 | F49: 0 | G49: =B49-C49-F49 -> 4673.4769 | H49: =H48+G49 -> 485124.71
A50: 47 | B50: ='P&L (36m)'!F49 -> 16904.931 | C50: ='P&L (36m)'!G49 -> 11554.035 | D50: =MonthlyDebtService -> 25879.512 | E50: =D50-C50 -> 14325.476 | F50: 0 | G50: =B50-C50-F50 -> 5350.8955 | H50: =H49+G50 -> 490475.6
A51: 48 | B51: ='P&L (36m)'!F50 -> 18218.763 | C51: ='P&L (36m)'!G50 -> 11440.625 | D51: =MonthlyDebtService -> 25879.512 | E51: =D51-C51 -> 14438.886 | F51: 0 | G51: =B51-C51-F51 -> 6778.1383 | H51: =H50+G51 -> 497253.74

Sheet KPIs
A1: Key Performance Indicators
A3: Metric | B3: Value | C3: Definition | D3: Formula
A4: Average Monthly Utilization (model input) | B4: =(Assumptions!B10*Assumptions!B11 + (1-Assumptions!B10)*Assumptions!B12) -> 0.535 | C4: Weighted usage rate | D4: PeakHoursShare*UtilPeak + (1-PeakHoursShare)*UtilOffPeak
A5: Revenue / Court / Hour (approx) | B5: ='Revenue Model'!B5 / (Assumptions!B7*Assumptions!B8*4.33*Assumptions!B9*(Assumptions!B10*Assumptions!B11 + (1-Assumptions!B10)*Assumptions!B12)) -> 21.843453 | C5: Efficiency measurement | D5: CourtRevenue / (Courts * Hours * Util * Days * Weeks)
A6: Payroll % of Revenue (Month 1) | B6: ='Staffing & Payroll'!E7 / 'Revenue Model'!I5 -> 0.41426966 | C6: Initial Cost ratio of Payroll | D6: MonthlyPayroll / TotalRevenue
A7: EBITDA Margin (Month 1) | B7: ='P&L (36m)'!F4/'P&L (36m)'!B4 -> -0.28146353 | C7: Initial Profitability margin | D7: EBITDA / Revenue
A8: Cash Runway (months) | B8: =IFERROR( 'Cash Flow'!H4 / ABS(AVERAGE('Cash Flow'!G5:G51)), 999) -> 68.796704 | C8: 0

Sheet Maintenance & Safety
A1: Preventive Maintenance Schedule
A3: Area/Asset | B3: Task | C3: Frequency | D3: Next Due | E3: Assigned To | F3: Status | G3: Notes
A4: Courts (surface/lines) | B4: Inspect/clean; check wear | C4: Monthly | F4: Open
A5: Lighting | B5: Test lux levels; replace failures | C5: Quarterly | F5: Open
A6: HVAC | B6: Filter change; service | C6: Quarterly | F6: Open
A7: Nets/Posts | B7: Tension & wear check | C7: Monthly | F7: Open
A8: Safety | B8: First-aid kits; AED check | C8: Monthly | F8: Open
A10: Incident Log
A11: Date | B11: Description | C11: Injury? (Y/N) | D11: Employee Involved | E11: Action Taken | F11: Follow-up Due

Sheet Events & Leagues
A1: Leagues & Events Tracker
A2: Use generators to export round-robin/brackets and paste key totals here.
A3: Event/League | B3: Start | C3: End | D3: Teams/Players | E3: Entry Fee | F3: Revenue | G3: Staff Hours | H3: Notes

Sheet README + Links
A1: How to Use This Workbook
A3: 1) Start at the Assumptions tab. Update blue cells (pricing, utilization, wages, rent, loan).
A4: 2) Fill CapEx & Sources. Adjust line items and contingency.
A5: 3) Revenue, P&L, Cash Flow, and KPIs will auto-update.
A7: Helpful External Templates (paste exports into tabs):
A8: Vertex42 Loan Amortization (Excel)
A9: LeagueLobster Round-Robin Generator
A10: Bracket Maker – Round Robin
A11: Marketing Budget Templates
A13: Notes:
A14: • Replace placeholder CapEx with vendor quotes. • If you prefer Google Sheets, upload this .xlsx—formulas will port cleanly. • Extend P&L/Cash Flow from 36 → 60 months by filling down.

Sheet Court Revenue OLD
A1: Court Revenue – Advanced Model (Peak/Off-Peak • Open Play • Members vs Non-Members)
A2: Paste into your master workbook. Link to Memberships tab for live members if desired.
A4: INPUTS – Facility & Scheduling | E4: INPUTS – Pricing
A5: Courts (count) | B5: 8 | E5: Peak rate – Non-member ($/court-hr) | F5: 70
A6: Days open per week | B6: 7 | E6: Off-peak rate – Non-member ($/court-hr) | F6: 50
A7: Hours open per day | B7: 14 | E7: Member discount on court rate | F7: 0.25
A8: Peak hours share of day | B8: 0.5 | E8: Open Play price – Member ($/session) | F8: 8
A9: Weekend share of days | B9: 0.28571429 | E9: Open Play price – Non-member ($/session) | F9: 12
A10: Avg reservation duration (min) | B10: 90 | E10: Open Play session length (min) | F10: 120
A11: Turn time between bookings (min) | B11: 5 | E11: Open Play players per court capacity (per hour) | F11: 6
E12: INPUTS – Membership Link (optional)
A13: INPUTS – Demand & Behavior | B13: Conservative Estimate | E13: Total Members: | F13: =Assumptions!B16 -> 50 | J13: Liberal Estimate
A14: Baseline utilization – Peak (weekday) | B14: 0.5 | E14: % Members who reserve monthly: | F14: 0.6 | J14: 0.75
A15: Baseline utilization – Off-peak (weekday) | B15: 0.3 | E15: Avg reservations per reserving member / month: | F15: 2 | J15: 0.4
A16: Baseline utilization – Peak (weekend) | B16: 0.7 | E16: Avg open play sessions per member / month: | F16: 1.2 | J16: 0.85
A17: Baseline utilization – Off-peak (weekend) | B17: 0.4 | J17: 0.5
A18: Member booking share of reservations | B18: 0.7 | J18: 0.7
A19: Booking window uplift (members vs non) | B19: 0.05 | J19: 0.05
A20: No-show rate (paid/no-refund portion) | B20: 0.05 | J20: 0.05
A21: Reservation share of total court time (vs open play) | B21: 0.5 | J21: 0.7
A23: HELPERS
A24: Court-hours available per month | B24: =B5*B6*4.33*B7 -> 3394.72
A25: Peak hours per month | B25: =B24*B8 -> 1697.36
A26: Off-peak hours per month | B26: =B24*(1-B8) -> 1697.36
A27: Bookings per court-day capacity (duration + turn) | B27: =FLOOR((B7*60)/(B10+B11),1) -> 8
A28: Reservation hours share | B28: =B21 -> 0.5
A29: Open Play hours share | B29: =(1-B21) -> 0.5
A30: Blended peak utilization (wkdy/wknd) | B30: =(1-B9)*B14+ B8*B16 -> 0.70714286
A31: Blended off-peak utilization (wkdy/wknd) | B31: =(1-B9)*B15 + B9*B17 -> 0.32857143
A33: RESERVATIONS – Revenue
A34: Segment | B34: Peak hours sold | C34: Off-peak hours sold | D34: Total hours (attended) | E34: Avg rate ($/hr) | F34: Revenue ($, attended)
A35: Members | B35: =B25*$B$30*$B$21*B18*(1+B19) -> 441.10143 | C35: =B26*$B$31*$B$21*$B$18*(1+$B$19) -> 204.95622 | D35: =B35+C35 -> 646.05765 | E35: =IFERROR(((F5*(1-F7))*B35 + (F6*(1-F7))*C35)/D35,0) -> 47.741379 | F35: =D35*E35 -> 30843.683
A36: Non-members | B36: =B25*$B$30*$B$21*(1-$B$18) -> 180.0414 | C36: =B26*$B$31*$B$21*(1-$B$18) -> 83.6556 | D36: =B36+C36 -> 263.697 | E36: =IFERROR((F5*B36 + F6*C36)/D36,0) -> 63.655172 | F36: =D36*E36 -> 16785.678
A37: Reservations TOTAL | B37: =B35+B36 -> 621.14283 | C37: =C35+C36 -> 288.61182 | D37: =D35+D36 -> 909.75465 | E37: =IFERROR((E35*D35+E36*D36)/D37,0) -> 52.354073 | F37: =F35+F36 -> 47629.361
A39: No-show charged revenue (policy-based, not in hours) | B39: =$E$37*$B$37*$B$20 -> 1625.9679
A41: OPEN PLAY – Revenue
A42: Segment | B42: Court-hours allocated | C42: Sessions (blocks) | D42: Players per hour | E42: Avg price/session | F42: Revenue ($)
A43: Members | B43: =(B29*B24)*$B$18 -> 1188.152 | C43: =IFERROR(B43/(F10/60),0) -> 594.076 | D43: =F11 -> 6 | E43: =F8 -> 8 | F43: =C43*E43 -> 4752.608
A44: Non-members | B44: =B29*B24*(1-$B$18) -> 509.208 | C44: =IFERROR(B44/(F10/60),0) -> 254.604 | D44: =F11 -> 6 | E44: =F9 -> 12 | F44: =C44*E44 -> 3055.248
A45: Open Play TOTAL | B45: =B43+B44 -> 1697.36 | C45: =C43+C44 -> 848.68 | F45: =F43+F44 -> 7807.856
...
